<?xml version="1.0" ?>
<!-- =================================================================================== -->
<!-- |    This document was autogenerated by xacro from /home/mcorsaro/kuka_ws/src/iiwa_robotiq/iiwa_robotiq_description/urdf/iiwa_robotiq.urdf.xacro | -->
<!-- |    EDITING THIS FILE BY HAND IS NOT RECOMMENDED                                 | -->
<!-- =================================================================================== -->
<!-- Here we define the robot, we named it "iiwa7_robotiq" -->
<robot name="iiwa7_robotiq" xmlns:xacro="http://www.ros.org/wiki/xacro">
  <material name="Black">
    <color rgba="0.0 0.0 0.0 1.0"/>
  </material>
  <material name="Blue">
    <color rgba="0.0 0.0 0.8 1.0"/>
  </material>
  <material name="Green">
    <color rgba="0.0 0.8 0.0 1.0"/>
  </material>
  <material name="Grey">
    <color rgba="0.4 0.4 0.4 1.0"/>
  </material>
  <material name="Orange">
    <color rgba="1.0 0.423529411765 0.0392156862745 1.0"/>
  </material>
  <material name="Brown">
    <color rgba="0.870588235294 0.811764705882 0.764705882353 1.0"/>
  </material>
  <material name="Red">
    <color rgba="0.8 0.0 0.0 1.0"/>
  </material>
  <material name="White">
    <color rgba="1.0 1.0 1.0 1.0"/>
  </material>
  <!-- Table surface centered 5 cm below the origin in the z direction. -->
  <link name="world">
    <visual>
      <origin rpy="0 0 0" xyz="0 0 -0.05"/>
      <geometry>
        <!-- 9.99cm thick so it doesn't intersect with arm model. -->
        <box size="2.5 2.5 0.0999"/>
      </geometry>
    </visual>
    <collision>
      <origin rpy="0 0 0" xyz="0 0 -0.05"/>
      <geometry>
        <box size="2.5 2.5 0.0999"/>
      </geometry>
    </collision>
  </link>
  <gazebo reference="world">
    <static>true</static>
  </gazebo>
  <!--joint between {parent} and link_0-->
  <joint name="world_iiwa_joint" type="fixed">
    <origin rpy="0 0 0" xyz="0 0 0"/>
    <parent link="world"/>
    <child link="iiwa_link_0"/>
  </joint>
  <link name="iiwa_link_0">
    <inertial>
      <origin rpy="0 0 0" xyz="-0.1 0 0.07"/>
      <mass value="5"/>
      <inertia ixx="0.05" ixy="0" ixz="0" iyy="0.06" iyz="0" izz="0.03"/>
    </inertial>
    <visual>
      <origin rpy="0 0 0" xyz="0 0 0"/>
      <geometry>
        <mesh filename="package://iiwa_description/meshes/iiwa7/visual/link_0.stl"/>
      </geometry>
      <material name="Grey"/>
    </visual>
    <collision>
      <origin rpy="0 0 0" xyz="0 0 0"/>
      <geometry>
        <mesh filename="package://iiwa_description/meshes/iiwa7/collision/link_0.stl"/>
      </geometry>
      <material name="Grey"/>
    </collision>
    <self_collision_checking>
      <origin rpy="0 0 0" xyz="0 0 0"/>
      <geometry>
        <capsule length="0.25" radius="0.15"/>
      </geometry>
    </self_collision_checking>
  </link>
  <!-- joint between link_0 and link_1 -->
  <joint name="iiwa_joint_1" type="revolute">
    <parent link="iiwa_link_0"/>
    <child link="iiwa_link_1"/>
    <origin rpy="0 0 0" xyz="0 0 0.15"/>
    <axis xyz="0 0 1"/>
    <limit effort="300" lower="-2.96705972839" upper="2.96705972839" velocity="10"/>
    <safety_controller k_position="100" k_velocity="2" soft_lower_limit="-2.93215314335" soft_upper_limit="2.93215314335"/>
    <dynamics damping="0.5"/>
  </joint>
  <link name="iiwa_link_1">
    <inertial>
      <origin rpy="0 0 0" xyz="0 -0.03 0.12"/>
      <mass value="3.4525"/>
      <inertia ixx="0.02183" ixy="0" ixz="0" iyy="0.007703" iyz="-0.003887" izz="0.02083"/>
    </inertial>
    <visual>
      <origin rpy="0 0 0" xyz="0 0 0.0075"/>
      <geometry>
        <mesh filename="package://iiwa_description/meshes/iiwa7/visual/link_1.stl"/>
      </geometry>
      <material name="Orange"/>
    </visual>
    <collision>
      <origin rpy="0 0 0" xyz="0 0 0.0075"/>
      <geometry>
        <mesh filename="package://iiwa_description/meshes/iiwa7/collision/link_1.stl"/>
      </geometry>
      <material name="Orange"/>
    </collision>
  </link>
  <joint name="iiwa_joint_2" type="revolute">
    <parent link="iiwa_link_1"/>
    <child link="iiwa_link_2"/>
    <origin rpy="1.57079632679   0 3.14159265359" xyz="0 0 0.19"/>
    <axis xyz="0 0 1"/>
    <limit effort="300" lower="-2.09439510239" upper="2.09439510239" velocity="10"/>
    <safety_controller k_position="100" k_velocity="2" soft_lower_limit="-2.05948851735" soft_upper_limit="2.05948851735"/>
    <dynamics damping="0.5"/>
  </joint>
  <link name="iiwa_link_2">
    <inertial>
      <origin rpy="0 0 0" xyz="0.0003 0.059 0.042"/>
      <mass value="3.4821"/>
      <inertia ixx="0.02076" ixy="0" ixz="-0.003626" iyy="0.02179" iyz="0" izz="0.00779"/>
    </inertial>
    <visual>
      <origin rpy="0 0 0" xyz="0 0 0"/>
      <geometry>
        <mesh filename="package://iiwa_description/meshes/iiwa7/visual/link_2.stl"/>
      </geometry>
      <material name="Orange"/>
    </visual>
    <collision>
      <origin rpy="0 0 0" xyz="0 0 0"/>
      <geometry>
        <mesh filename="package://iiwa_description/meshes/iiwa7/collision/link_2.stl"/>
      </geometry>
      <material name="Orange"/>
    </collision>
  </link>
  <joint name="iiwa_joint_3" type="revolute">
    <parent link="iiwa_link_2"/>
    <child link="iiwa_link_3"/>
    <origin rpy="1.57079632679 0 3.14159265359" xyz="0 0.21 0"/>
    <axis xyz="0 0 1"/>
    <limit effort="300" lower="-2.96705972839" upper="2.96705972839" velocity="10"/>
    <safety_controller k_position="100" k_velocity="2" soft_lower_limit="-2.93215314335" soft_upper_limit="2.93215314335"/>
    <dynamics damping="0.5"/>
  </joint>
  <link name="iiwa_link_3">
    <inertial>
      <origin rpy="0 0 0" xyz="0 0.03 0.13"/>
      <mass value="4.05623"/>
      <inertia ixx="0.03204" ixy="0" ixz="0" iyy="0.00972" iyz="0.006227" izz="0.03042"/>
    </inertial>
    <visual>
      <origin rpy="0 0 0" xyz="0 0 -0.026"/>
      <geometry>
        <mesh filename="package://iiwa_description/meshes/iiwa7/visual/link_3.stl"/>
      </geometry>
      <material name="Orange"/>
    </visual>
    <collision>
      <origin rpy="0 0 0" xyz="0 0 -0.026"/>
      <geometry>
        <mesh filename="package://iiwa_description/meshes/iiwa7/collision/link_3.stl"/>
      </geometry>
      <material name="Orange"/>
    </collision>
  </link>
  <joint name="iiwa_joint_4" type="revolute">
    <parent link="iiwa_link_3"/>
    <child link="iiwa_link_4"/>
    <origin rpy="1.57079632679 0 0" xyz="0 0 0.19"/>
    <axis xyz="0 0 1"/>
    <limit effort="300" lower="-2.09439510239" upper="2.09439510239" velocity="10"/>
    <safety_controller k_position="100" k_velocity="2" soft_lower_limit="-2.05948851735" soft_upper_limit="2.05948851735"/>
    <dynamics damping="0.5"/>
  </joint>
  <link name="iiwa_link_4">
    <inertial>
      <origin rpy="0 0 0" xyz="0 0.067 0.034"/>
      <mass value="3.4822"/>
      <inertia ixx="0.02178" ixy="0" ixz="0" iyy="0.02075" iyz="-0.003625" izz="0.007785"/>
    </inertial>
    <visual>
      <origin rpy="0 0 0" xyz="0 0 0"/>
      <geometry>
        <mesh filename="package://iiwa_description/meshes/iiwa7/visual/link_4.stl"/>
      </geometry>
      <material name="Orange"/>
    </visual>
    <collision>
      <origin rpy="0 0 0" xyz="0 0 0"/>
      <geometry>
        <mesh filename="package://iiwa_description/meshes/iiwa7/collision/link_4.stl"/>
      </geometry>
      <material name="Orange"/>
    </collision>
  </link>
  <joint name="iiwa_joint_5" type="revolute">
    <parent link="iiwa_link_4"/>
    <child link="iiwa_link_5"/>
    <origin rpy="-1.57079632679 3.14159265359 0" xyz="0 0.21 0"/>
    <axis xyz="0 0 1"/>
    <limit effort="300" lower="-2.96705972839" upper="2.96705972839" velocity="10"/>
    <safety_controller k_position="100" k_velocity="2" soft_lower_limit="-2.93215314335" soft_upper_limit="2.93215314335"/>
    <dynamics damping="0.5"/>
  </joint>
  <link name="iiwa_link_5">
    <inertial>
      <origin rpy="0 0 0" xyz="0.0001 0.021 0.076"/>
      <mass value="2.1633"/>
      <inertia ixx="0.01287" ixy="0" ixz="0" iyy="0.005708" iyz="-0.003946" izz="0.01112"/>
    </inertial>
    <visual>
      <origin rpy="0 0 0" xyz="0 0 -0.026"/>
      <geometry>
        <mesh filename="package://iiwa_description/meshes/iiwa7/visual/link_5.stl"/>
      </geometry>
      <material name="Orange"/>
    </visual>
    <collision>
      <origin rpy="0 0 0" xyz="0 0 -0.026"/>
      <geometry>
        <mesh filename="package://iiwa_description/meshes/iiwa7/collision/link_5.stl"/>
      </geometry>
      <material name="Orange"/>
    </collision>
  </link>
  <joint name="iiwa_joint_6" type="revolute">
    <parent link="iiwa_link_5"/>
    <child link="iiwa_link_6"/>
    <origin rpy="1.57079632679 0 0" xyz="0 0.06070 0.19"/>
    <axis xyz="0 0 1"/>
    <limit effort="300" lower="-2.09439510239" upper="2.09439510239" velocity="10"/>
    <safety_controller k_position="100" k_velocity="2" soft_lower_limit="-2.05948851735" soft_upper_limit="2.05948851735"/>
    <dynamics damping="0.5"/>
  </joint>
  <link name="iiwa_link_6">
    <inertial>
      <origin rpy="0 0 0" xyz="0 0.0006 0.0004"/>
      <mass value="2.3466"/>
      <inertia ixx="0.006509" ixy="0" ixz="0" iyy="0.006259" iyz="0.00031891" izz="0.004527"/>
    </inertial>
    <visual>
      <origin rpy="0 0 0" xyz="0 0 0"/>
      <geometry>
        <mesh filename="package://iiwa_description/meshes/iiwa7/visual/link_6.stl"/>
      </geometry>
      <material name="Orange"/>
    </visual>
    <collision>
      <origin rpy="0 0 0" xyz="0 0 0"/>
      <geometry>
        <mesh filename="package://iiwa_description/meshes/iiwa7/collision/link_6.stl"/>
      </geometry>
      <material name="Orange"/>
    </collision>
  </link>
  <joint name="iiwa_joint_7" type="revolute">
    <parent link="iiwa_link_6"/>
    <child link="iiwa_link_7"/>
    <origin rpy="-1.57079632679 3.14159265359 0" xyz="0 0.081 0.06070"/>
    <axis xyz="0 0 1"/>
    <limit effort="300" lower="-3.05432619099" upper="3.05432619099" velocity="10"/>
    <safety_controller k_position="100" k_velocity="2" soft_lower_limit="-3.01941960595" soft_upper_limit="3.01941960595"/>
    <dynamics damping="0.5"/>
  </joint>
  <link name="iiwa_link_7">
    <inertial>
      <origin rpy="0 0 0" xyz="0 0 0.02"/>
      <mass value="3.129"/>
      <inertia ixx="0.01464" ixy="0.0005912" ixz="0" iyy="0.01465" iyz="0" izz="0.002872"/>
    </inertial>
    <visual>
      <origin rpy="0 0 0" xyz="0 0 -0.0005"/>
      <geometry>
        <mesh filename="package://iiwa_description/meshes/iiwa7/visual/link_7.stl"/>
      </geometry>
      <material name="Grey"/>
    </visual>
    <collision>
      <origin rpy="0 0 0" xyz="0 0 -0.0005"/>
      <geometry>
        <mesh filename="package://iiwa_description/meshes/iiwa7/collision/link_7.stl"/>
      </geometry>
      <material name="Grey"/>
    </collision>
  </link>
  <joint name="iiwa_joint_ee" type="fixed">
    <parent link="iiwa_link_7"/>
    <child link="iiwa_link_ee"/>
    <origin rpy="0 0 0" xyz="0 0 0.045"/>
  </joint>
  <link name="iiwa_link_ee">
    </link>
  <!-- Load Gazebo lib and set the robot namespace -->
  <gazebo>
    <plugin filename="libgazebo_ros_control.so" name="gazebo_ros_control">
      <robotNamespace>/iiwa</robotNamespace>
    </plugin>
  </gazebo>
  <!-- Link0 -->
  <gazebo reference="iiwa_link_0">
    <material>Gazebo/Grey</material>
    <mu1>0.2</mu1>
    <mu2>0.2</mu2>
  </gazebo>
  <!-- Link1 -->
  <gazebo reference="iiwa_link_1">
    <material>Gazebo/Orange</material>
    <mu1>0.2</mu1>
    <mu2>0.2</mu2>
  </gazebo>
  <!-- Link2 -->
  <gazebo reference="iiwa_link_2">
    <material>Gazebo/Orange</material>
    <mu1>0.2</mu1>
    <mu2>0.2</mu2>
  </gazebo>
  <!-- Link3 -->
  <gazebo reference="iiwa_link_3">
    <material>Gazebo/Orange</material>
    <mu1>0.2</mu1>
    <mu2>0.2</mu2>
  </gazebo>
  <!-- Link4 -->
  <gazebo reference="iiwa_link_4">
    <material>Gazebo/Orange</material>
    <mu1>0.2</mu1>
    <mu2>0.2</mu2>
  </gazebo>
  <!-- Link5 -->
  <gazebo reference="iiwa_link_5">
    <material>Gazebo/Orange</material>
    <mu1>0.2</mu1>
    <mu2>0.2</mu2>
  </gazebo>
  <!-- Link6 -->
  <gazebo reference="iiwa_link_6">
    <material>Gazebo/Orange</material>
    <mu1>0.2</mu1>
    <mu2>0.2</mu2>
  </gazebo>
  <!-- Link7 -->
  <gazebo reference="iiwa_link_7">
    <material>Gazebo/Grey</material>
    <mu1>0.2</mu1>
    <mu2>0.2</mu2>
  </gazebo>
  <transmission name="iiwa_tran_1">
    <robotNamespace>/iiwa</robotNamespace>
    <type>transmission_interface/SimpleTransmission</type>
    <joint name="iiwa_joint_1">
      <hardwareInterface>PositionJointInterface</hardwareInterface>
    </joint>
    <actuator name="iiwa_motor_1">
      <hardwareInterface>PositionJointInterface</hardwareInterface>
      <mechanicalReduction>1</mechanicalReduction>
    </actuator>
  </transmission>
  <transmission name="iiwa_tran_2">
    <robotNamespace>/iiwa</robotNamespace>
    <type>transmission_interface/SimpleTransmission</type>
    <joint name="iiwa_joint_2">
      <hardwareInterface>PositionJointInterface</hardwareInterface>
    </joint>
    <actuator name="iiwa_motor_2">
      <hardwareInterface>PositionJointInterface</hardwareInterface>
      <mechanicalReduction>1</mechanicalReduction>
    </actuator>
  </transmission>
  <transmission name="iiwa_tran_3">
    <robotNamespace>/iiwa</robotNamespace>
    <type>transmission_interface/SimpleTransmission</type>
    <joint name="iiwa_joint_3">
      <hardwareInterface>PositionJointInterface</hardwareInterface>
    </joint>
    <actuator name="iiwa_motor_3">
      <hardwareInterface>PositionJointInterface</hardwareInterface>
      <mechanicalReduction>1</mechanicalReduction>
    </actuator>
  </transmission>
  <transmission name="iiwa_tran_4">
    <robotNamespace>/iiwa</robotNamespace>
    <type>transmission_interface/SimpleTransmission</type>
    <joint name="iiwa_joint_4">
      <hardwareInterface>PositionJointInterface</hardwareInterface>
    </joint>
    <actuator name="iiwa_motor_4">
      <hardwareInterface>PositionJointInterface</hardwareInterface>
      <mechanicalReduction>1</mechanicalReduction>
    </actuator>
  </transmission>
  <transmission name="iiwa_tran_5">
    <robotNamespace>/iiwa</robotNamespace>
    <type>transmission_interface/SimpleTransmission</type>
    <joint name="iiwa_joint_5">
      <hardwareInterface>PositionJointInterface</hardwareInterface>
    </joint>
    <actuator name="iiwa_motor_5">
      <hardwareInterface>PositionJointInterface</hardwareInterface>
      <mechanicalReduction>1</mechanicalReduction>
    </actuator>
  </transmission>
  <transmission name="iiwa_tran_6">
    <robotNamespace>/iiwa</robotNamespace>
    <type>transmission_interface/SimpleTransmission</type>
    <joint name="iiwa_joint_6">
      <hardwareInterface>PositionJointInterface</hardwareInterface>
    </joint>
    <actuator name="iiwa_motor_6">
      <hardwareInterface>PositionJointInterface</hardwareInterface>
      <mechanicalReduction>1</mechanicalReduction>
    </actuator>
  </transmission>
  <transmission name="iiwa_tran_7">
    <robotNamespace>/iiwa</robotNamespace>
    <type>transmission_interface/SimpleTransmission</type>
    <joint name="iiwa_joint_7">
      <hardwareInterface>PositionJointInterface</hardwareInterface>
    </joint>
    <actuator name="iiwa_motor_7">
      <hardwareInterface>PositionJointInterface</hardwareInterface>
      <mechanicalReduction>1</mechanicalReduction>
    </actuator>
  </transmission>
  <!-- link list -->
  <link name="finger_1_link_0">
    <visual>
      <origin rpy="0 0 0" xyz="0.020 0 0"/>
      <geometry>
        <mesh filename="package://robotiq_3f_gripper_visualization/meshes/robotiq-3f-gripper_articulated/visual/link_0.STL"/>
      </geometry>
      <material name="gray">
        <color rgba="0.2 0.2 0.2 1"/>
      </material>
    </visual>
    <collision>
      <origin rpy="0 0 0" xyz="0.020 0 0"/>
      <geometry>
        <mesh filename="package://robotiq_3f_gripper_visualization/meshes/robotiq-3f-gripper_articulated/collision/link_0.STL"/>
      </geometry>
      <material name="yellow">
        <color rgba="0 1 1 1"/>
      </material>
    </collision>
    <inertial>
      <origin rpy="0 0 0" xyz="0 0 0"/>
      <mass value="0.05"/>
      <inertia ixx="0.01" ixy="-0.00002" ixz="0.00001" iyy="0.0008" iyz="0" izz="0.001"/>
    </inertial>
  </link>
  <link name="finger_1_link_1">
    <visual>
      <origin rpy="0 0 -0.52" xyz="0.050 -.028 0"/>
      <geometry>
        <mesh filename="package://robotiq_3f_gripper_visualization/meshes/robotiq-3f-gripper_articulated/visual/link_1.STL"/>
      </geometry>
      <material name="gray"/>
    </visual>
    <collision>
      <origin rpy="0 0 -0.52" xyz="0.050 -.028 0"/>
      <geometry>
        <mesh filename="package://robotiq_3f_gripper_visualization/meshes/robotiq-3f-gripper_articulated/collision/link_1.STL"/>
      </geometry>
      <material name="yellow"/>
    </collision>
    <inertial>
      <origin rpy="0 0 0" xyz="0 0 0"/>
      <mass value="0.15"/>
      <inertia ixx="0.001859" ixy="-0.000376" ixz="0.000028" iyy="0.012756" iyz="0" izz="0.0024"/>
    </inertial>
  </link>
  <link name="finger_1_link_2">
    <!--
\t\t\tNOTE: This link has an offset in the z-direction based on the models that were
\t\t\tused to generate grap-it poses.  With the offset below the model appears visually
\t\t\tcorrect, but it is suspect.
\t\t\t-->
    <visual>
      <origin rpy="0 0 0" xyz="0.039 0 0.0075"/>
      <geometry>
        <mesh filename="package://robotiq_3f_gripper_visualization/meshes/robotiq-3f-gripper_articulated/visual/link_2.STL"/>
      </geometry>
      <material name="gray"/>
    </visual>
    <collision>
      <origin rpy="0 0 0" xyz="0.039 0 0.0075"/>
      <geometry>
        <mesh filename="package://robotiq_3f_gripper_visualization/meshes/robotiq-3f-gripper_articulated/collision/link_2.STL"/>
      </geometry>
      <material name="yellow"/>
    </collision>
    <inertial>
      <origin rpy="0 0 0" xyz="0 0 0"/>
      <mass value="0.15"/>
      <inertia ixx="0.001859" ixy="-0.000376" ixz="0.000028" iyy="0.012756" iyz="0" izz="0.0024"/>
    </inertial>
  </link>
  <link name="finger_1_link_3">
    <visual>
      <origin rpy="0 0 0.52" xyz="0 0 0"/>
      <geometry>
        <mesh filename="package://robotiq_3f_gripper_visualization/meshes/robotiq-3f-gripper_articulated/visual/link_3.STL"/>
      </geometry>
      <material name="gray"/>
    </visual>
    <collision>
      <origin rpy="0 0 0.52" xyz="0 0 0"/>
      <geometry>
        <mesh filename="package://robotiq_3f_gripper_visualization/meshes/robotiq-3f-gripper_articulated/collision/link_3.STL"/>
      </geometry>
      <material name="yellow"/>
    </collision>
    <inertial>
      <origin rpy="0 0 0" xyz="0 0 0"/>
      <mass value="0.05"/>
      <inertia ixx="0.001239" ixy="-0.000251" ixz="0.000019" iyy="0.00085" iyz="0" izz="0.001632"/>
    </inertial>
  </link>
  <!-- end of link list -->
  <!-- joint list -->
  <joint name="finger_1_joint_1" type="revolute">
    <parent link="finger_1_link_0"/>
    <child link="finger_1_link_1"/>
    <axis xyz="0 0 1"/>
    <origin rpy="0 0 0" xyz="0.020 0 0"/>
    <limit effort="100" lower="0.0495" upper="1.2218" velocity="100"/>
  </joint>
  <joint name="finger_1_joint_2" type="revolute">
    <parent link="finger_1_link_1"/>
    <child link="finger_1_link_2"/>
    <axis xyz="0 0 1"/>
    <origin rpy="0 0 -0.52" xyz="0.050 -.028 0"/>
    <limit effort="100" lower="0.0" upper="1.5708" velocity="100"/>
  </joint>
  <joint name="finger_1_joint_3" type="revolute">
    <parent link="finger_1_link_2"/>
    <child link="finger_1_link_3"/>
    <axis xyz="0 0 1"/>
    <origin rpy="0 0 0" xyz="0.039 0 0"/>
    <limit effort="100" lower="-1.2217" upper="-0.0523" velocity="100"/>
  </joint>
  <!-- end of joint list -->
  <!-- link list -->
  <link name="finger_2_link_0">
    <visual>
      <origin rpy="0 0 0" xyz="0.020 0 0"/>
      <geometry>
        <mesh filename="package://robotiq_3f_gripper_visualization/meshes/robotiq-3f-gripper_articulated/visual/link_0.STL"/>
      </geometry>
      <material name="gray">
        <color rgba="0.2 0.2 0.2 1"/>
      </material>
    </visual>
    <collision>
      <origin rpy="0 0 0" xyz="0.020 0 0"/>
      <geometry>
        <mesh filename="package://robotiq_3f_gripper_visualization/meshes/robotiq-3f-gripper_articulated/collision/link_0.STL"/>
      </geometry>
      <material name="yellow">
        <color rgba="0 1 1 1"/>
      </material>
    </collision>
    <inertial>
      <origin rpy="0 0 0" xyz="0 0 0"/>
      <mass value="0.05"/>
      <inertia ixx="0.01" ixy="-0.00002" ixz="0.00001" iyy="0.0008" iyz="0" izz="0.001"/>
    </inertial>
  </link>
  <link name="finger_2_link_1">
    <visual>
      <origin rpy="0 0 -0.52" xyz="0.050 -.028 0"/>
      <geometry>
        <mesh filename="package://robotiq_3f_gripper_visualization/meshes/robotiq-3f-gripper_articulated/visual/link_1.STL"/>
      </geometry>
      <material name="gray"/>
    </visual>
    <collision>
      <origin rpy="0 0 -0.52" xyz="0.050 -.028 0"/>
      <geometry>
        <mesh filename="package://robotiq_3f_gripper_visualization/meshes/robotiq-3f-gripper_articulated/collision/link_1.STL"/>
      </geometry>
      <material name="yellow"/>
    </collision>
    <inertial>
      <origin rpy="0 0 0" xyz="0 0 0"/>
      <mass value="0.15"/>
      <inertia ixx="0.001859" ixy="-0.000376" ixz="0.000028" iyy="0.012756" iyz="0" izz="0.0024"/>
    </inertial>
  </link>
  <link name="finger_2_link_2">
    <!--
\t\t\tNOTE: This link has an offset in the z-direction based on the models that were
\t\t\tused to generate grap-it poses.  With the offset below the model appears visually
\t\t\tcorrect, but it is suspect.
\t\t\t-->
    <visual>
      <origin rpy="0 0 0" xyz="0.039 0 0.0075"/>
      <geometry>
        <mesh filename="package://robotiq_3f_gripper_visualization/meshes/robotiq-3f-gripper_articulated/visual/link_2.STL"/>
      </geometry>
      <material name="gray"/>
    </visual>
    <collision>
      <origin rpy="0 0 0" xyz="0.039 0 0.0075"/>
      <geometry>
        <mesh filename="package://robotiq_3f_gripper_visualization/meshes/robotiq-3f-gripper_articulated/collision/link_2.STL"/>
      </geometry>
      <material name="yellow"/>
    </collision>
    <inertial>
      <origin rpy="0 0 0" xyz="0 0 0"/>
      <mass value="0.15"/>
      <inertia ixx="0.001859" ixy="-0.000376" ixz="0.000028" iyy="0.012756" iyz="0" izz="0.0024"/>
    </inertial>
  </link>
  <link name="finger_2_link_3">
    <visual>
      <origin rpy="0 0 0.52" xyz="0 0 0"/>
      <geometry>
        <mesh filename="package://robotiq_3f_gripper_visualization/meshes/robotiq-3f-gripper_articulated/visual/link_3.STL"/>
      </geometry>
      <material name="gray"/>
    </visual>
    <collision>
      <origin rpy="0 0 0.52" xyz="0 0 0"/>
      <geometry>
        <mesh filename="package://robotiq_3f_gripper_visualization/meshes/robotiq-3f-gripper_articulated/collision/link_3.STL"/>
      </geometry>
      <material name="yellow"/>
    </collision>
    <inertial>
      <origin rpy="0 0 0" xyz="0 0 0"/>
      <mass value="0.05"/>
      <inertia ixx="0.001239" ixy="-0.000251" ixz="0.000019" iyy="0.00085" iyz="0" izz="0.001632"/>
    </inertial>
  </link>
  <!-- end of link list -->
  <!-- joint list -->
  <joint name="finger_2_joint_1" type="revolute">
    <parent link="finger_2_link_0"/>
    <child link="finger_2_link_1"/>
    <axis xyz="0 0 1"/>
    <origin rpy="0 0 0" xyz="0.020 0 0"/>
    <limit effort="100" lower="0.0495" upper="1.2218" velocity="100"/>
  </joint>
  <joint name="finger_2_joint_2" type="revolute">
    <parent link="finger_2_link_1"/>
    <child link="finger_2_link_2"/>
    <axis xyz="0 0 1"/>
    <origin rpy="0 0 -0.52" xyz="0.050 -.028 0"/>
    <limit effort="100" lower="0.0" upper="1.5708" velocity="100"/>
  </joint>
  <joint name="finger_2_joint_3" type="revolute">
    <parent link="finger_2_link_2"/>
    <child link="finger_2_link_3"/>
    <axis xyz="0 0 1"/>
    <origin rpy="0 0 0" xyz="0.039 0 0"/>
    <limit effort="100" lower="-1.2217" upper="-0.0523" velocity="100"/>
  </joint>
  <!-- end of joint list -->
  <!-- link list -->
  <link name="finger_middle_link_0">
    <visual>
      <origin rpy="0 0 0" xyz="0.020 0 0"/>
      <geometry>
        <mesh filename="package://robotiq_3f_gripper_visualization/meshes/robotiq-3f-gripper_articulated/visual/link_0.STL"/>
      </geometry>
      <material name="gray">
        <color rgba="0.2 0.2 0.2 1"/>
      </material>
    </visual>
    <collision>
      <origin rpy="0 0 0" xyz="0.020 0 0"/>
      <geometry>
        <mesh filename="package://robotiq_3f_gripper_visualization/meshes/robotiq-3f-gripper_articulated/collision/link_0.STL"/>
      </geometry>
      <material name="yellow">
        <color rgba="0 1 1 1"/>
      </material>
    </collision>
    <inertial>
      <origin rpy="0 0 0" xyz="0 0 0"/>
      <mass value="0.05"/>
      <inertia ixx="0.01" ixy="-0.00002" ixz="0.00001" iyy="0.0008" iyz="0" izz="0.001"/>
    </inertial>
  </link>
  <link name="finger_middle_link_1">
    <visual>
      <origin rpy="0 0 -0.52" xyz="0.050 -.028 0"/>
      <geometry>
        <mesh filename="package://robotiq_3f_gripper_visualization/meshes/robotiq-3f-gripper_articulated/visual/link_1.STL"/>
      </geometry>
      <material name="gray"/>
    </visual>
    <collision>
      <origin rpy="0 0 -0.52" xyz="0.050 -.028 0"/>
      <geometry>
        <mesh filename="package://robotiq_3f_gripper_visualization/meshes/robotiq-3f-gripper_articulated/collision/link_1.STL"/>
      </geometry>
      <material name="yellow"/>
    </collision>
    <inertial>
      <origin rpy="0 0 0" xyz="0 0 0"/>
      <mass value="0.15"/>
      <inertia ixx="0.001859" ixy="-0.000376" ixz="0.000028" iyy="0.012756" iyz="0" izz="0.0024"/>
    </inertial>
  </link>
  <link name="finger_middle_link_2">
    <!--
\t\t\tNOTE: This link has an offset in the z-direction based on the models that were
\t\t\tused to generate grap-it poses.  With the offset below the model appears visually
\t\t\tcorrect, but it is suspect.
\t\t\t-->
    <visual>
      <origin rpy="0 0 0" xyz="0.039 0 0.0075"/>
      <geometry>
        <mesh filename="package://robotiq_3f_gripper_visualization/meshes/robotiq-3f-gripper_articulated/visual/link_2.STL"/>
      </geometry>
      <material name="gray"/>
    </visual>
    <collision>
      <origin rpy="0 0 0" xyz="0.039 0 0.0075"/>
      <geometry>
        <mesh filename="package://robotiq_3f_gripper_visualization/meshes/robotiq-3f-gripper_articulated/collision/link_2.STL"/>
      </geometry>
      <material name="yellow"/>
    </collision>
    <inertial>
      <origin rpy="0 0 0" xyz="0 0 0"/>
      <mass value="0.15"/>
      <inertia ixx="0.001859" ixy="-0.000376" ixz="0.000028" iyy="0.012756" iyz="0" izz="0.0024"/>
    </inertial>
  </link>
  <link name="finger_middle_link_3">
    <visual>
      <origin rpy="0 0 0.52" xyz="0 0 0"/>
      <geometry>
        <mesh filename="package://robotiq_3f_gripper_visualization/meshes/robotiq-3f-gripper_articulated/visual/link_3.STL"/>
      </geometry>
      <material name="gray"/>
    </visual>
    <collision>
      <origin rpy="0 0 0.52" xyz="0 0 0"/>
      <geometry>
        <mesh filename="package://robotiq_3f_gripper_visualization/meshes/robotiq-3f-gripper_articulated/collision/link_3.STL"/>
      </geometry>
      <material name="yellow"/>
    </collision>
    <inertial>
      <origin rpy="0 0 0" xyz="0 0 0"/>
      <mass value="0.05"/>
      <inertia ixx="0.001239" ixy="-0.000251" ixz="0.000019" iyy="0.00085" iyz="0" izz="0.001632"/>
    </inertial>
  </link>
  <!-- end of link list -->
  <!-- joint list -->
  <joint name="finger_middle_joint_1" type="revolute">
    <parent link="finger_middle_link_0"/>
    <child link="finger_middle_link_1"/>
    <axis xyz="0 0 1"/>
    <origin rpy="0 0 0" xyz="0.020 0 0"/>
    <limit effort="100" lower="0.0495" upper="1.2218" velocity="100"/>
  </joint>
  <joint name="finger_middle_joint_2" type="revolute">
    <parent link="finger_middle_link_1"/>
    <child link="finger_middle_link_2"/>
    <axis xyz="0 0 1"/>
    <origin rpy="0 0 -0.52" xyz="0.050 -.028 0"/>
    <limit effort="100" lower="0.0" upper="1.5708" velocity="100"/>
  </joint>
  <joint name="finger_middle_joint_3" type="revolute">
    <parent link="finger_middle_link_2"/>
    <child link="finger_middle_link_3"/>
    <axis xyz="0 0 1"/>
    <origin rpy="0 0 0" xyz="0.039 0 0"/>
    <limit effort="100" lower="-1.2217" upper="-0.0523" velocity="100"/>
  </joint>
  <!-- end of joint list -->
  <!-- link list -->
  <link name="palm">
    <visual>
      <geometry>
        <mesh filename="package://robotiq_3f_gripper_visualization/meshes/robotiq-3f-gripper_articulated/visual/palm.STL"/>
      </geometry>
      <material name="gray">
        <color rgba="0.2 0.2 0.2 1"/>
      </material>
    </visual>
    <collision>
      <geometry>
        <mesh filename="package://robotiq_3f_gripper_visualization/meshes/robotiq-3f-gripper_articulated/collision/palm.STL"/>
      </geometry>
      <material name="yellow">
        <color rgba="0 1 1 1"/>
      </material>
    </collision>
  </link>
  <link name="tool0"/>
  <inertial>
    <origin rpy="0 0 0" xyz="0 0 0"/>
    <mass value="1.3"/>
    <inertia ixx="0.006012" ixy="0.000079" ixz="-0.00024" iyy="0.012892" iyz="0" izz="0.002435"/>
  </inertial>
  <!-- end of link list -->
  <!-- joint list -->
  <joint name="palm_finger_1_joint" type="revolute">
    <parent link="palm"/>
    <child link="finger_1_link_0"/>
    <axis xyz="0 1 0"/>
    <origin rpy="0 3.1416 -1.57" xyz="-0.0455 0.0214 0.036"/>
    <limit effort="100" lower="-0.1784" upper="0.192" velocity="100"/>
  </joint>
  <joint name="palm_finger_2_joint" type="revolute">
    <parent link="palm"/>
    <child link="finger_2_link_0"/>
    <axis xyz="0 1 0"/>
    <origin rpy="0 3.1416 -1.57" xyz="-0.0455 0.0214 -0.036"/>
    <limit effort="100" lower="-0.192" upper="0.1784" velocity="100"/>
  </joint>
  <joint name="palm_finger_middle_joint" type="fixed">
    <parent link="palm"/>
    <child link="finger_middle_link_0"/>
    <axis xyz="0 0 1"/>
    <origin rpy="0 0 1.57" xyz="0.0455 0.0214 0"/>
  </joint>
  <joint name="palm_tool0" type="fixed">
    <parent link="palm"/>
    <child link="tool0"/>
    <origin rpy="0 0 1.5707" xyz="0.0 0.0875 0.0"/>
  </joint>
  <!-- end of joint list -->
  <!-- Here we define a flange link between the tip of the iiwa7 and the base of the robotiq. -->
  <!-- Insert a cylinder between default (smaller) flange and robotiq. -->
  <link name="flange">
    <visual>
      <geometry>
        <!-- Length and radius computed by SGD (Semi-stochastic GraduateStudent Descent). -->
        <cylinder length="0.038" radius="0.035"/>
      </geometry>
      <material name="orange">
        <color rgba="1.0 0.27 0.0 1"/>
      </material>
    </visual>
    <collision>
      <geometry>
        <cylinder length="0.038" radius="0.035"/>
      </geometry>
    </collision>
  </link>
  <!-- Link at surface of palm for planning. -->
  <link name="palm_surface"/>
  <!-- Link near the center of the grasp region for planning. -->
  <link name="finger_grasp_centroid"/>
  <!-- The offset between iiwa_link_ee and palm was estimated to be 0.0975.
       Sum of z origin displacements of ee_to_flange and robotiq_joint. -->
  <joint name="ee_to_flange" type="fixed">
    <parent link="iiwa_link_ee"/>
    <child link="flange"/>
    <origin xyz="0.0 0.0 0.0225"/>
  </joint>
  <joint name="robotiq_joint" type="fixed">
    <parent link="flange"/>
    <child link="palm"/>
    <origin rpy="1.57079632679 0 1.57079632679" xyz="0.0 0.0 0.075"/>
  </joint>
  <joint name="palm_to_palm_surface" type="fixed">
    <parent link="palm"/>
    <child link="palm_surface"/>
    <!-- Also estimated heuristically. -->
    <origin xyz="0.0 0.05 0.0"/>
  </joint>
  <joint name="palm_to_finger_grasp_centroid" type="fixed">
    <parent link="palm"/>
    <child link="finger_grasp_centroid"/>
    <!-- Also estimated heuristically. -->
    <origin xyz="0.0 0.125 0.0"/>
  </joint>
</robot>

